========================================
MUFON Import Started: Tue Aug 19 02:00:01 AM PDT 2025
========================================
Traceback (most recent call last):
  File "<frozen runpy>", line 198, in _run_module_as_main
  File "<frozen runpy>", line 88, in _run_code
  File "/home/mike/D/ufobeep/api/app/services/mufon_scraper.py", line 333, in <module>
    asyncio.run(run_nightly_import())
  File "/usr/lib/python3.12/asyncio/runners.py", line 194, in run
    return runner.run(main)
           ^^^^^^^^^^^^^^^^
  File "/usr/lib/python3.12/asyncio/runners.py", line 118, in run
    return self._loop.run_until_complete(task)
           ^^^^^^^^^^^^^^^^^^^^^^^^^^^^^^^^^^^
  File "/usr/lib/python3.12/asyncio/base_events.py", line 687, in run_until_complete
    return future.result()
           ^^^^^^^^^^^^^^^
  File "/home/mike/D/ufobeep/api/app/services/mufon_scraper.py", line 285, in run_nightly_import
    db_pool = await asyncpg.create_pool(
              ^^^^^^^^^^^^^^^^^^^^^^^^^^
  File "/home/mike/D/ufobeep/api/venv/lib/python3.12/site-packages/asyncpg/pool.py", line 418, in _async__init__
    await self._initialize()
  File "/home/mike/D/ufobeep/api/venv/lib/python3.12/site-packages/asyncpg/pool.py", line 445, in _initialize
    await first_ch.connect()
  File "/home/mike/D/ufobeep/api/venv/lib/python3.12/site-packages/asyncpg/pool.py", line 132, in connect
    self._con = await self._pool._get_new_connection()
                ^^^^^^^^^^^^^^^^^^^^^^^^^^^^^^^^^^^^^^
  File "/home/mike/D/ufobeep/api/venv/lib/python3.12/site-packages/asyncpg/pool.py", line 517, in _get_new_connection
    con = await self._connect(
          ^^^^^^^^^^^^^^^^^^^^
  File "/home/mike/D/ufobeep/api/venv/lib/python3.12/site-packages/asyncpg/connection.py", line 2421, in connect
    return await connect_utils._connect(
           ^^^^^^^^^^^^^^^^^^^^^^^^^^^^^
  File "/home/mike/D/ufobeep/api/venv/lib/python3.12/site-packages/asyncpg/connect_utils.py", line 1075, in _connect
    raise last_error or exceptions.TargetServerAttributeNotMatched(
  File "/home/mike/D/ufobeep/api/venv/lib/python3.12/site-packages/asyncpg/connect_utils.py", line 1049, in _connect
    conn = await _connect_addr(
           ^^^^^^^^^^^^^^^^^^^^
  File "/home/mike/D/ufobeep/api/venv/lib/python3.12/site-packages/asyncpg/connect_utils.py", line 886, in _connect_addr
    return await __connect_addr(params, True, *args)
           ^^^^^^^^^^^^^^^^^^^^^^^^^^^^^^^^^^^^^^^^^
  File "/home/mike/D/ufobeep/api/venv/lib/python3.12/site-packages/asyncpg/connect_utils.py", line 931, in __connect_addr
    tr, pr = await connector
             ^^^^^^^^^^^^^^^
  File "/home/mike/D/ufobeep/api/venv/lib/python3.12/site-packages/asyncpg/connect_utils.py", line 802, in _create_ssl_connection
    tr, pr = await loop.create_connection(
             ^^^^^^^^^^^^^^^^^^^^^^^^^^^^^
  File "/usr/lib/python3.12/asyncio/base_events.py", line 1122, in create_connection
    raise exceptions[0]
  File "/usr/lib/python3.12/asyncio/base_events.py", line 1104, in create_connection
    sock = await self._connect_sock(
           ^^^^^^^^^^^^^^^^^^^^^^^^^
  File "/usr/lib/python3.12/asyncio/base_events.py", line 1007, in _connect_sock
    await self.sock_connect(sock, address)
  File "/usr/lib/python3.12/asyncio/selector_events.py", line 651, in sock_connect
    return await fut
           ^^^^^^^^^
  File "/usr/lib/python3.12/asyncio/selector_events.py", line 691, in _sock_connect_cb
    raise OSError(err, f'Connect call failed {address}')
ConnectionRefusedError: [Errno 111] Connect call failed ('127.0.0.1', 5432)
Import failed at Tue Aug 19 02:00:01 AM PDT 2025
========================================
